Traceback (most recent call last):
  File "/home/ubuntu/.local/lib/python3.10/site-packages/jupyter_cache/executors/utils.py", line 58, in single_nb_execution
    executenb(
  File "/home/ubuntu/.local/lib/python3.10/site-packages/nbclient/client.py", line 1305, in execute
    return NotebookClient(nb=nb, resources=resources, km=km, **kwargs).execute()
  File "/home/ubuntu/.local/lib/python3.10/site-packages/jupyter_core/utils/__init__.py", line 172, in wrapped
    return loop.run_until_complete(inner)
  File "/usr/lib/python3.10/asyncio/base_events.py", line 649, in run_until_complete
    return future.result()
  File "/home/ubuntu/.local/lib/python3.10/site-packages/nbclient/client.py", line 705, in async_execute
    await self.async_execute_cell(
  File "/home/ubuntu/.local/lib/python3.10/site-packages/nbclient/client.py", line 1058, in async_execute_cell
    await self._check_raise_for_error(cell, cell_index, exec_reply)
  File "/home/ubuntu/.local/lib/python3.10/site-packages/nbclient/client.py", line 914, in _check_raise_for_error
    raise CellExecutionError.from_cell_and_msg(cell, exec_reply_content)
nbclient.exceptions.CellExecutionError: An error occurred while executing the following cell:
------------------
our_newly_sampled_data = nib.load("../new_data/sub-01_ses-01_task-fixedbar_run-1_space-T1w_desc-preproc_bold_depth-1.0.func.gii").agg_data()
previous_sampled_data = nib.load("derivatives/fmriprep/sub-01/ses-01/func/sub-01_ses-01_task-fixedbar_run-1_hemi-L_space-fsnative_bold.func.gii").agg_data()

assert our_newly_sampled_data.shape == previous_sampled_data.shape, "Sampled data is not correct!"
------------------


[0;31m---------------------------------------------------------------------------[0m
[0;31mFileNotFoundError[0m                         Traceback (most recent call last)
File [0;32m~/.local/lib/python3.10/site-packages/nibabel/loadsave.py:101[0m, in [0;36mload[0;34m(filename, **kwargs)[0m
[1;32m    100[0m [38;5;28;01mtry[39;00m:
[0;32m--> 101[0m     stat_result [38;5;241m=[39m [43mos[49m[38;5;241;43m.[39;49m[43mstat[49m[43m([49m[43mfilename[49m[43m)[49m
[1;32m    102[0m [38;5;28;01mexcept[39;00m [38;5;167;01mOSError[39;00m:

[0;31mFileNotFoundError[0m: [Errno 2] No such file or directory: '../new_data/sub-01_ses-01_task-fixedbar_run-1_space-T1w_desc-preproc_bold_depth-1.0.func.gii'

During handling of the above exception, another exception occurred:

[0;31mFileNotFoundError[0m                         Traceback (most recent call last)
Cell [0;32mIn[9], line 1[0m
[0;32m----> 1[0m our_newly_sampled_data [38;5;241m=[39m [43mnib[49m[38;5;241;43m.[39;49m[43mload[49m[43m([49m[38;5;124;43m"[39;49m[38;5;124;43m../new_data/sub-01_ses-01_task-fixedbar_run-1_space-T1w_desc-preproc_bold_depth-1.0.func.gii[39;49m[38;5;124;43m"[39;49m[43m)[49m[38;5;241m.[39magg_data()
[1;32m      2[0m previous_sampled_data [38;5;241m=[39m nib[38;5;241m.[39mload([38;5;124m"[39m[38;5;124mderivatives/fmriprep/sub-01/ses-01/func/sub-01_ses-01_task-fixedbar_run-1_hemi-L_space-fsnative_bold.func.gii[39m[38;5;124m"[39m)[38;5;241m.[39magg_data()
[1;32m      4[0m [38;5;28;01massert[39;00m our_newly_sampled_data[38;5;241m.[39mshape [38;5;241m==[39m previous_sampled_data[38;5;241m.[39mshape, [38;5;124m"[39m[38;5;124mSampled data is not correct![39m[38;5;124m"[39m

File [0;32m~/.local/lib/python3.10/site-packages/nibabel/loadsave.py:103[0m, in [0;36mload[0;34m(filename, **kwargs)[0m
[1;32m    101[0m     stat_result [38;5;241m=[39m os[38;5;241m.[39mstat(filename)
[1;32m    102[0m [38;5;28;01mexcept[39;00m [38;5;167;01mOSError[39;00m:
[0;32m--> 103[0m     [38;5;28;01mraise[39;00m [38;5;167;01mFileNotFoundError[39;00m([38;5;124mf[39m[38;5;124m"[39m[38;5;124mNo such file or no access: [39m[38;5;124m'[39m[38;5;132;01m{[39;00mfilename[38;5;132;01m}[39;00m[38;5;124m'[39m[38;5;124m"[39m)
[1;32m    104[0m [38;5;28;01mif[39;00m stat_result[38;5;241m.[39mst_size [38;5;241m<[39m[38;5;241m=[39m [38;5;241m0[39m:
[1;32m    105[0m     [38;5;28;01mraise[39;00m ImageFileError([38;5;124mf[39m[38;5;124m"[39m[38;5;124mEmpty file: [39m[38;5;124m'[39m[38;5;132;01m{[39;00mfilename[38;5;132;01m}[39;00m[38;5;124m'[39m[38;5;124m"[39m)

[0;31mFileNotFoundError[0m: No such file or no access: '../new_data/sub-01_ses-01_task-fixedbar_run-1_space-T1w_desc-preproc_bold_depth-1.0.func.gii'

